Workbook

Sheet Guests
A1: 🪁 TARIFA WEEKEND — GUEST LIST
A3: # | B3: Guest Name | C3: Nickname
A4: 1 | B4: Laura
A5: 2 | B5: Alex
A6: 3 | B6: Luis
A7: 4 | B7: Matt
A8: 5 | B8: Paul
A9: 6 | B9: Vic
A10: 7 | B10: Sara
A11: 8 | B11: Selin
A12: 9 | B12: Pedram
A13: 10 | B13: Tyler
A14: 11 | B14: Emmi

Sheet Expenses
A1: 💰 EXPENSE LOG
F2: =Guests!B4 -> Laura | G2: =Guests!B5 -> Alex | H2: =Guests!B6 -> Luis | I2: =Guests!B7 -> Matt | J2: =Guests!B8 -> Paul | K2: =Guests!B9 -> Vic | L2: =Guests!B10 -> Sara | M2: =Guests!B11 -> Selin | N2: =Guests!B12 -> Pedram | O2: =Guests!B13 -> Tyler | P2: =Guests!B14 -> Emmi
A3: Date | B3: Description | C3: Category | D3: Paid By | E3: Total Amount (€) | F3: Guest 1? | G3: Guest 2? | H3: Guest 3? | I3: Guest 4? | J3: Guest 5? | K3: Guest 6? | L3: Guest 7? | M3: Guest 8? | N3: Guest 9? | O3: Guest 10? | P3: Guest 11? | Q3: # Splitting | R3: Per Person
A4: 46142 | B4: Thursday diner | C4: Food | D4: Pedram | E4: 220 | F4: 1 | G4: 1 | J4: 1 | K4: 1 | N4: 1 | Q4: =COUNTIF(F4:P4,"1") -> 5 | R4: =IF(Q4>0,E4/Q4,0) -> 44
A5: 46143 | B5: Friday Breakfast | C5: Food | D5: Luis | E5: 183 | F5: 1 | G5: 1 | H5: 1 | J5: 1 | K5: 1 | L5: 1 | M5: 1 | O5: 1 | Q5: =COUNTIF(F5:P5,"1") -> 8 | R5: =IF(Q5>0,E5/Q5,0) -> 22.875
A6: 46144 | B6: Saturday Breakfast | C6: Food | D6: Laura | E6: 107 | F6: 1 | G6: 1 | H6: 1 | J6: 1 | K6: 1 | Q6: =COUNTIF(F6:P6,"1") -> 5 | R6: =IF(Q6>0,E6/Q6,0) -> 21.4
A7: 46145 | B7: Sunday Breakfast | C7: Food | D7: Laura | E7: 55 | F7: 1 | G7: 1 | H7: 1 | I7: 1 | J7: 1 | K7: 1 | L7: 1 | M7: 1 | N7: 1 | O7: 1 | P7: 1 | Q7: =COUNTIF(F7:P7,"1") -> 11 | R7: =IF(Q7>0,E7/Q7,0) -> 5
A8: 46144 | B8: Rooftop Drinks | C8: Food | D8: Alex | E8: 65 | F8: 1 | G8: 1 | H8: 1 | I8: 1 | J8: 1 | K8: 1 | L8: 1 | M8: 1 | N8: 1 | O8: 1 | Q8: =COUNTIF(F8:P8,"1") -> 10 | R8: =IF(Q8>0,E8/Q8,0) -> 6.5
A9: 30/04-03/05 | B9: Airbnb 1 | C9: Accommodation | D9: Laura | E9: 844 | F9: 1 | G9: 1 | H9: 1 | J9: 1 | K9: 1 | L9: 1 | Q9: =COUNTIF(F9:P9,"1") -> 6 | R9: =IF(Q9>0,E9/Q9,0) -> 140.66667
A10: 02/05 - 03/05 | B10: Airbnb 1 | C10: Accommodation | D10: Laura | E10: 47 | I10: 1 | Q10: =COUNTIF(F10:P10,"1") -> 1 | R10: =IF(Q10>0,E10/Q10,0) -> 47
A11: 30/04-04/05 | B11: Airbnb 2 | C11: Accommodation | D11: Laura | E11: 1313.38 | M11: 1 | N11: 1 | O11: 1 | P11: 1 | Q11: =COUNTIF(F11:P11,"1") -> 4 | R11: =IF(Q11>0,E11/Q11,0) -> 328.345
A12: 03/05-04/05 | B12: Hotel | C12: Accommodation | D12: Laura | E12: 300 | F12: 1 | H12: 1 | I12: 1 | Q12: =COUNTIF(F12:P12,"1") -> 3 | R12: =IF(Q12>0,E12/Q12,0) -> 100
A13: 30/04-04/05 | B13: Car rental | C13: Transport | D13: Laura | E13: 250 | F13: 1 | H13: 1 | L13: 1 | Q13: =COUNTIF(F13:P13,"1") -> 3 | R13: =IF(Q13>0,E13/Q13,0) -> 83.333333
A14: 30/04-04/05 | B14: Kite Alex | C14: Kitesurf | D14: Laura | E14: 428 | G14: 1 | Q14: =COUNTIF(F14:P14,"1") -> 1 | R14: =IF(Q14>0,E14/Q14,0) -> 428
A15: 46144 | B15: Kite Emmi | C15: Kitesurf | D15: Laura | E15: 160 | P15: 1 | Q15: =COUNTIF(F15:P15,"1") -> 1 | R15: =IF(Q15>0,E15/Q15,0) -> 160
A16: 30/04-04/05 | B16: Kite Pedram | C16: Kitesurf | D16: Laura | E16: 160 | N16: 1 | Q16: =COUNTIF(F16:P16,"1") -> 1 | R16: =IF(Q16>0,E16/Q16,0) -> 160
A17: 46146 | B17: Velvet Kimono | C17: Other | D17: Laura | E17: 98 | P17: 1 | Q17: =COUNTIF(F17:P17,"1") -> 1 | R17: =IF(Q17>0,E17/Q17,0) -> 98
Q18: =COUNTIF(F18:P18,"1") -> 0 | R18: =IF(Q18>0,E18/Q18,0) -> 0
Q19: =COUNTIF(F19:P19,"1") -> 0 | R19: =IF(Q19>0,E19/Q19,0) -> 0
Q20: =COUNTIF(F20:P20,"1") -> 0 | R20: =IF(Q20>0,E20/Q20,0) -> 0
Q21: =COUNTIF(F21:P21,"1") -> 0 | R21: =IF(Q21>0,E21/Q21,0) -> 0
Q22: =COUNTIF(F22:P22,"1") -> 0 | R22: =IF(Q22>0,E22/Q22,0) -> 0
Q23: =COUNTIF(F23:P23,"1") -> 0 | R23: =IF(Q23>0,E23/Q23,0) -> 0
Q24: =COUNTIF(F24:P24,"1") -> 0 | R24: =IF(Q24>0,E24/Q24,0) -> 0
Q25: =COUNTIF(F25:P25,"1") -> 0 | R25: =IF(Q25>0,E25/Q25,0) -> 0
Q26: =COUNTIF(F26:P26,"1") -> 0 | R26: =IF(Q26>0,E26/Q26,0) -> 0
Q27: =COUNTIF(F27:P27,"1") -> 0 | R27: =IF(Q27>0,E27/Q27,0) -> 0
Q28: =COUNTIF(F28:P28,"1") -> 0 | R28: =IF(Q28>0,E28/Q28,0) -> 0
Q29: =COUNTIF(F29:P29,"1") -> 0 | R29: =IF(Q29>0,E29/Q29,0) -> 0
... Q33: =COUNTIF(F33:P33,"1") -> 0 | R33: =IF(Q33>0,E33/Q33,0) -> 0
A35: HOW TO USE:
A36: 1. Enter date, description, category, who paid, total amount
A37: 2. Put '1' under each guest splitting this expense
A38: 3. Leave blank for guests NOT included
A39: 4. Summary sheet calculates everything automatically!
A40: Categories: Food, Transport, Accommodation, Kitesurf, Drinks, Activities, Other

Sheet Summary
A1: 📊 WHO OWES WHAT — SUMMARY
A3: Guest | B3: Total Paid | C3: Total Owed | D3: Balance | E3: Status
A4: =Guests!B4 -> Laura | B4: =SUMPRODUCT((Expenses!D4:D33=Guests!B4)*Expenses!E4:E33) -> 3664.38 | C4: =SUMPRODUCT((Expenses!F4:F33=1)*Expenses!R4:R33) -> 423.775 | D4: =B4-C4 -> 3240.605 | E4: =IF(D4>0,"Is owed €" & TEXT(D4,"#,##0.00"),IF(D4<0,"Owes €" & TEXT(ABS(D4),"#,##0.00"),"Settled ✅")) -> Is owed €3,240.61
A5: =Guests!B5 -> Alex | B5: =SUMPRODUCT((Expenses!D4:D33=Guests!B5)*Expenses!E4:E33) -> 65 | C5: =SUMPRODUCT((Expenses!G4:G33=1)*Expenses!R4:R33) -> 668.44167 | D5: =B5-C5 -> -603.44167 | E5: =IF(D5>0,"Is owed €" & TEXT(D5,"#,##0.00"),IF(D5<0,"Owes €" & TEXT(ABS(D5),"#,##0.00"),"Settled ✅")) -> Owes €603.44
A6: =Guests!B6 -> Luis | B6: =SUMPRODUCT((Expenses!D4:D33=Guests!B6)*Expenses!E4:E33) -> 183 | C6: =SUMPRODUCT((Expenses!H4:H33=1)*Expenses!R4:R33) -> 379.775 | D6: =B6-C6 -> -196.775 | E6: =IF(D6>0,"Is owed €" & TEXT(D6,"#,##0.00"),IF(D6<0,"Owes €" & TEXT(ABS(D6),"#,##0.00"),"Settled ✅")) -> Owes €196.78
A7: =Guests!B7 -> Matt | B7: =SUMPRODUCT((Expenses!D4:D33=Guests!B7)*Expenses!E4:E33) -> 0 | C7: =SUMPRODUCT((Expenses!I4:I33=1)*Expenses!R4:R33) -> 158.5 | D7: =B7-C7 -> -158.5 | E7: =IF(D7>0,"Is owed €" & TEXT(D7,"#,##0.00"),IF(D7<0,"Owes €" & TEXT(ABS(D7),"#,##0.00"),"Settled ✅")) -> Owes €158.50
A8: =Guests!B8 -> Paul | B8: =SUMPRODUCT((Expenses!D4:D33=Guests!B8)*Expenses!E4:E33) -> 0 | C8: =SUMPRODUCT((Expenses!J4:J33=1)*Expenses!R4:R33) -> 240.44167 | D8: =B8-C8 -> -240.44167 | E8: =IF(D8>0,"Is owed €" & TEXT(D8,"#,##0.00"),IF(D8<0,"Owes €" & TEXT(ABS(D8),"#,##0.00"),"Settled ✅")) -> Owes €240.44
A9: =Guests!B9 -> Vic | B9: =SUMPRODUCT((Expenses!D4:D33=Guests!B9)*Expenses!E4:E33) -> 0 | C9: =SUMPRODUCT((Expenses!K4:K33=1)*Expenses!R4:R33) -> 240.44167 | D9: =B9-C9 -> -240.44167 | E9: =IF(D9>0,"Is owed €" & TEXT(D9,"#,##0.00"),IF(D9<0,"Owes €" & TEXT(ABS(D9),"#,##0.00"),"Settled ✅")) -> Owes €240.44
A10: =Guests!B10 -> Sara | B10: =SUMPRODUCT((Expenses!D4:D33=Guests!B10)*Expenses!E4:E33) -> 0 | C10: =SUMPRODUCT((Expenses!L4:L33=1)*Expenses!R4:R33) -> 258.375 | D10: =B10-C10 -> -258.375 | E10: =IF(D10>0,"Is owed €" & TEXT(D10,"#,##0.00"),IF(D10<0,"Owes €" & TEXT(ABS(D10),"#,##0.00"),"Settled ✅")) -> Owes €258.38
A11: =Guests!B11 -> Selin | B11: =SUMPRODUCT((Expenses!D4:D33=Guests!B11)*Expenses!E4:E33) -> 0 | C11: =SUMPRODUCT((Expenses!M4:M33=1)*Expenses!R4:R33) -> 362.72 | D11: =B11-C11 -> -362.72 | E11: =IF(D11>0,"Is owed €" & TEXT(D11,"#,##0.00"),IF(D11<0,"Owes €" & TEXT(ABS(D11),"#,##0.00"),"Settled ✅")) -> Owes €362.72
A12: =Guests!B12 -> Pedram | B12: =SUMPRODUCT((Expenses!D4:D33=Guests!B12)*Expenses!E4:E33) -> 220 | C12: =SUMPRODUCT((Expenses!N4:N33=1)*Expenses!R4:R33) -> 543.845 | D12: =B12-C12 -> -323.845 | E12: =IF(D12>0,"Is owed €" & TEXT(D12,"#,##0.00"),IF(D12<0,"Owes €" & TEXT(ABS(D12),"#,##0.00"),"Settled ✅")) -> Owes €323.85
A13: =Guests!B13 -> Tyler | B13: =SUMPRODUCT((Expenses!D4:D33=Guests!B13)*Expenses!E4:E33) -> 0 | C13: =SUMPRODUCT((Expenses!O4:O33=1)*Expenses!R4:R33) -> 362.72 | D13: =B13-C13 -> -362.72 | E13: =IF(D13>0,"Is owed €" & TEXT(D13,"#,##0.00"),IF(D13<0,"Owes €" & TEXT(ABS(D13),"#,##0.00"),"Settled ✅")) -> Owes €362.72
A14: =Guests!B14 -> Emmi | B14: =SUMPRODUCT((Expenses!D4:D33=Guests!B14)*Expenses!E4:E33) -> 0 | C14: =SUMPRODUCT((Expenses!P4:P33=1)*Expenses!R4:R33) -> 591.345 | D14: =B14-C14 -> -591.345 | E14: =IF(D14>0,"Is owed €" & TEXT(D14,"#,##0.00"),IF(D14<0,"Owes €" & TEXT(ABS(D14),"#,##0.00"),"Settled ✅")) -> Owes €591.35
A15: TOTAL | B15: =SUM(B4:B14) -> 4132.38 | C15: =SUM(C4:C14) -> 4230.38
A17: 💸 WHO PAYS WHO — SETTLEMENT PLAN
A18: Send these amounts to settle all debts:
A20: Who Pays | B20: → | C20: Pays To | D20: Amount (€)
A21: Emmi | B21: → | C21: Laura | D21: 591.35
A22: Alex | B22: → | C22: Laura | D22: 588.57
A23: Pedram | B23: → | C23: Laura | D23: 449.35
A24: Selin | B24: → | C24: Laura | D24: 333.35
A25: Tyler | B25: → | C25: Laura | D25: 333.35
A26: Luis | B26: → | C26: Laura | D26: 327.52
A27: Sara | B27: → | C27: Laura | D27: 229
A28: Paul | B28: → | C28: Laura | D28: 167.07
A29: Vic | B29: → | C29: Laura | D29: 167.07
A30: Matt | B30: → | C30: Laura | D30: 152
A31: Paul | B31: → | C31: Pedram | D31: 44
A32: Vic | B32: → | C32: Pedram | D32: 44
... A45: Matt | B45: → | C45: Alex | D45: 6.5
A48: 📋 INDIVIDUAL ACTIONS
A50: Person | B50: Action | C50: To Whom | D50: Amount
A51: Laura | B51: Receives | C51: from everyone below ↑ | D51: 3377.63
A52: Alex | B52: Pays | C52: Laura | D52: 588.57
A53: Alex | B53: Pays | C53: Pedram | D53: 37.5
A54: Alex | B54: Pays | C54: Luis | D54: 16.38
A55: Luis | B55: Pays | C55: Laura | D55: 327.52
A56: Matt | B56: Pays | C56: Laura | D56: 152
A57: Matt | B57: Pays | C57: Alex | D57: 6.5
A58: Paul | B58: Pays | C58: Laura | D58: 167.07
...
